Workbook

Sheet Instructions
A1: Sheet Name | B1: Column | C1: Required | D1: Valid Values | E1: Description
A2: General | E2: Fill out each sheet with your organization data. Team Names must match exactly across sheets.
A4: Teams | B4: Team Name | C4: Yes | E4: Unique name for the team (e.g., Day Shift Team)
A5: Teams | B5: Description | C5: No | E5: Brief description of the team's purpose
A6: Teams | B6: Shift Schedule | C6: No | E6: Operating hours (e.g., 6:00 AM - 2:00 PM)
A8: Departments | B8: Department Name | C8: Yes | E8: Name of the department (e.g., Machining)
A9: Departments | B9: Team Name | C9: Yes | E9: Must match a Team Name from the Teams sheet
A10: Departments | B10: Description | C10: No | E10: Brief description of the department
A12: Stations | B12: Station ID | C12: Yes | E12: Unique identifier (e.g., CNC-001)
A13: Stations | B13: Station Name | C13: Yes | E13: Descriptive name for the station
A14: Stations | B14: Work Center | C14: Yes | E14: Physical area grouping (e.g., CNC Bay 1)
A15: Stations | B15: Work Center Type | C15: Yes | D15: See Valid Values sheet | E15: Type of work center
A16: Stations | B16: Team Name | C16: No | E16: Must match a Team Name if provided
A17: Stations | B17: Department | C17: No | E17: Department assignment
A18: Stations | B18: Active | C18: No | D18: yes, no | E18: Whether station is currently in use
A20: Users | B20: Email | C20: Yes | E20: Valid email address
A21: Users | B21: Display Name | C21: Yes | E21: User's display name
A22: Users | B22: App Role | C22: Yes | D22: admin, supervisor, operator, viewer | E22: Application-level role
A23: Users | B23: Org Role | C23: No | D23: owner, admin, member | E23: Organization-level role
A24: Users | B24: Team Role | C24: No | D24: owner, admin, member | E24: Team-level role
A25: Users | B25: Team Name | C25: No | E25: Must match a Team Name if provided
A26: Users | B26: Department | C26: No | E26: Department assignment
A28: Work Orders | B28: Work Order # | C28: Yes | E28: Unique work order identifier
A29: Work Orders | B29: Title | C29: Yes | E29: Brief title for the work order
A30: Work Orders | B30: Part Number | C30: No | E30: Associated part number
A31: Work Orders | B31: Operation # | C31: No | E31: Operation/step number
A32: Work Orders | B32: Quantity | C32: No | E32: Number of parts
A33: Work Orders | B33: Priority | C33: No | D33: low, normal, high, urgent, critical | E33: Priority level
A34: Work Orders | B34: Status | C34: No | D34: pending, queued, in_progress, on_hold | E34: Current status
A35: Work Orders | B35: Station ID | C35: No | E35: Must match a Station ID if provided
A36: Work Orders | B36: Team Name | C36: No | E36: Must match a Team Name if provided
A37: Work Orders | B37: Due Date | C37: No | E37: Format: YYYY-MM-DD
A38: Work Orders | B38: Est. Duration | C38: No | E38: Estimated minutes to complete
A39: Work Orders | B39: Tags | C39: No | E39: Comma-separated tags
A40: Work Orders | B40: Description | C40: No | E40: Detailed description
A42: Routing Templates | B42: Template Name | C42: Yes | E42: Name of the routing template
A43: Routing Templates | B43: Part Number Pattern | C43: Yes | E43: Wildcard pattern to match part numbers (e.g., PART-*)
A44: Routing Templates | B44: Step # | C44: Yes | E44: Sequential step number within the template
A45: Routing Templates | B45: Operation Name | C45: Yes | E45: Name of the operation/step
A46: Routing Templates | B46: Type | C46: Yes | D46: See Valid Values sheet | E46: Step type (quote, engineering, internal, etc.)
...

Sheet Teams
A1: Team Name | B1: Description | C1: Shift Schedule (optional)
A2: Day Shift Team | B2: Primary day shift operations team, 6AM-2PM | C2: 6:00 AM - 2:00 PM
A3: Night Shift Team | B3: Night shift operations, 10PM-6AM | C3: 10:00 PM - 6:00 AM
A4: Swing Shift Team | B4: Swing shift coverage, 2PM-10PM | C4: 2:00 PM - 10:00 PM
A5: Welding Team | B5: Specialized welding and fabrication team | C5: 7:00 AM - 3:30 PM
A6: Quality Team | B6: Quality assurance and inspection team | C6: 7:00 AM - 3:30 PM

Sheet Departments
A1: Department Name | B1: Team Name | C1: Description (optional) | D1: Team Valid?
A2: Machining | B2: Day Shift Team | C2: CNC milling and lathe operations | D2: =IF(B2="","",IF(COUNTIF(Teams!A$2:A$6,B2)>0,"✓","✗ Not Found")) -> ✓
A3: Machining - Night | B3: Night Shift Team | C3: CNC milling and lathe operations - night shift | D3: =IF(B3="","",IF(COUNTIF(Teams!A$2:A$6,B3)>0,"✓","✗ Not Found")) -> ✓
A4: Fabrication | B4: Welding Team | C4: Welding and sheet metal work | D4: =IF(B4="","",IF(COUNTIF(Teams!A$2:A$6,B4)>0,"✓","✗ Not Found")) -> ✓
A5: Quality | B5: Quality Team | C5: Inspection and QC operations | D5: =IF(B5="","",IF(COUNTIF(Teams!A$2:A$6,B5)>0,"✓","✗ Not Found")) -> ✓
A6: Shipping | B6: Day Shift Team | C6: Packaging and logistics | D6: =IF(B6="","",IF(COUNTIF(Teams!A$2:A$6,B6)>0,"✓","✗ Not Found")) -> ✓
A7: Assembly | B7: Day Shift Team | C7: Final assembly and hardware installation | D7: =IF(B7="","",IF(COUNTIF(Teams!A$2:A$6,B7)>0,"✓","✗ Not Found")) -> ✓
A8: Cutting | B8: Day Shift Team | C8: Saw and waterjet cutting operations | D8: =IF(B8="","",IF(COUNTIF(Teams!A$2:A$6,B8)>0,"✓","✗ Not Found")) -> ✓
A9: Engineering | B9: Day Shift Team | C9: Engineering review and CAM programming | D9: =IF(B9="","",IF(COUNTIF(Teams!A$2:A$6,B9)>0,"✓","✗ Not Found")) -> ✓
A10: Admin | B10: Day Shift Team | C10: Quoting, purchasing, and receiving operations | D10: =IF(B10="","",IF(COUNTIF(Teams!A$2:A$6,B10)>0,"✓","✗ Not Found")) -> ✓

Sheet Stations
A1: Station ID | B1: Station Name | C1: Work Center | D1: Work Center Type | E1: Team Name (optional) | F1: Department (optional) | G1: Active (yes/no) | H1: Team Valid?
A2: CNC-001 | B2: Haas VF-2 Mill #1 | C2: CNC Bay 1 | D2: CNC Mill | E2: Day Shift Team | F2: Machining | G2: yes | H2: =IF(E2="","",IF(COUNTIF(Teams!A$2:A$6,E2)>0,"✓","✗ Not Found")) -> ✓
A3: CNC-002 | B3: Haas VF-2 Mill #2 | C3: CNC Bay 1 | D3: CNC Mill | E3: Day Shift Team | F3: Machining | G3: yes | H3: =IF(E3="","",IF(COUNTIF(Teams!A$2:A$6,E3)>0,"✓","✗ Not Found")) -> ✓
A4: LATHE-001 | B4: Mazak QT-250 Lathe | C4: CNC Bay 2 | D4: CNC Lathe | E4: Night Shift Team | F4: Machining | G4: yes | H4: =IF(E4="","",IF(COUNTIF(Teams!A$2:A$6,E4)>0,"✓","✗ Not Found")) -> ✓
A5: WJ-001 | B5: Flow Waterjet | C5: Cutting Area | D5: Water Jet | F5: Cutting | G5: yes | H5: =IF(E5="","",IF(COUNTIF(Teams!A$2:A$6,E5)>0,"✓","✗ Not Found"))
A6: WELD-001 | B6: TIG Station 1 | C6: Welding Bay | D6: TIG Welding | E6: Welding Team | F6: Fabrication | G6: yes | H6: =IF(E6="","",IF(COUNTIF(Teams!A$2:A$6,E6)>0,"✓","✗ Not Found")) -> ✓
A7: INSP-001 | B7: CMM Station | C7: Quality Lab | D7: Outgoing Inspection | F7: Quality | G7: yes | H7: =IF(E7="","",IF(COUNTIF(Teams!A$2:A$6,E7)>0,"✓","✗ Not Found"))
A8: SAW-001 | B8: Saw Station 1 | C8: Cutting Area | D8: Band Saw | F8: Cutting | G8: yes | H8: =IF(E8="","",IF(COUNTIF(Teams!A$2:A$6,E8)>0,"✓","✗ Not Found"))
A9: DEB-001 | B9: Deburr Station 1 | C9: Finishing Area | D9: Deburr Station | G9: yes | H9: =IF(E9="","",IF(COUNTIF(Teams!A$2:A$6,E9)>0,"✓","✗ Not Found"))
A10: PKG-001 | B10: Packaging Station 1 | C10: Shipping Area | D10: Shipping | F10: Shipping | G10: yes | H10: =IF(E10="","",IF(COUNTIF(Teams!A$2:A$6,E10)>0,"✓","✗ Not Found"))
A11: CMM-001 | B11: CMM Inspection 1 | C11: Quality Lab | D11: Incoming Inspection | F11: Quality | G11: yes | H11: =IF(E11="","",IF(COUNTIF(Teams!A$2:A$6,E11)>0,"✓","✗ Not Found"))
A12: QUOTE-001 | B12: Quoting Station | C12: Front Office | D12: Quoting | E12: Day Shift Team | F12: Admin | G12: yes | H12: =IF(E12="","",IF(COUNTIF(Teams!A$2:A$6,E12)>0,"✓","✗ Not Found")) -> ✓
A13: ENG-001 | B13: Engineering Station | C13: Engineering Office | D13: Engineering Review | E13: Day Shift Team | F13: Engineering | G13: yes | H13: =IF(E13="","",IF(COUNTIF(Teams!A$2:A$6,E13)>0,"✓","✗ Not Found")) -> ✓
A14: CAM-001 | B14: CAM Programming Station | C14: Engineering Office | D14: CAM Programming | E14: Day Shift Team | F14: Engineering | G14: yes | H14: =IF(E14="","",IF(COUNTIF(Teams!A$2:A$6,E14)>0,"✓","✗ Not Found")) -> ✓
A15: PUR-001 | B15: Purchasing Station | C15: Front Office | D15: Purchasing | E15: Day Shift Team | F15: Admin | G15: yes | H15: =IF(E15="","",IF(COUNTIF(Teams!A$2:A$6,E15)>0,"✓","✗ Not Found")) -> ✓
A16: REC-001 | B16: Receiving Station | C16: Receiving Area | D16: Receiving | E16: Day Shift Team | F16: Admin | G16: yes | H16: =IF(E16="","",IF(COUNTIF(Teams!A$2:A$6,E16)>0,"✓","✗ Not Found")) -> ✓
A17: TOOL-001 | B17: Tool Crib Station | C17: Tool Crib Area | D17: Tool Crib | E17: Day Shift Team | F17: Machining | G17: yes | H17: =IF(E17="","",IF(COUNTIF(Teams!A$2:A$6,E17)>0,"✓","✗ Not Found")) -> ✓
A18: FINSP-001 | B18: Final Inspection Station | C18: Quality Lab | D18: Final Inspection | E18: Quality Team | F18: Quality | G18: yes | H18: =IF(E18="","",IF(COUNTIF(Teams!A$2:A$6,E18)>0,"✓","✗ Not Found")) -> ✓
A19: GRIND-001 | B19: Grinding Station | C19: CNC Bay 2 | D19: Grinding | E19: Day Shift Team | F19: Machining | G19: yes | H19: =IF(E19="","",IF(COUNTIF(Teams!A$2:A$6,E19)>0,"✓","✗ Not Found")) -> ✓
A20: ASSY-001 | B20: Assembly Station 1 | C20: Assembly Area | D20: Hardware Installation | E20: Day Shift Team | F20: Assembly | G20: yes | H20: =IF(E20="","",IF(COUNTIF(Teams!A$2:A$6,E20)>0,"✓","✗ Not Found")) -> ✓

Sheet Stations - Valid Values
A1: Column | B1: Valid Values
A2: Work Center Type | B2: CNC Mill, CNC Lathe, Water Jet, Band Saw, Press Brake, TIG Welding, MIG Welding, Electron Beam Welding, Punch Press, Hardware Installation, Deburr Station, Shipping, Incoming Inspection, Outgoing Inspection, Tool Crib, Quoting, Engineering Review, CAM Programming, Purchasing, Receiving, Final Inspection, Grinding
A3: Active (yes/no) | B3: yes, no

Sheet Users
A1: Email | B1: Display Name | C1: App Role | D1: Org Role (optional) | E1: Team Role (optional) | F1: Team Name (optional) | G1: Department (optional) | H1: Team Valid?
A2: john.smith@company.com | B2: John Smith | C2: operator | D2: member | E2: member | F2: Day Shift Team | G2: Machining | H2: =IF(F2="","",IF(COUNTIF(Teams!A$2:A$6,F2)>0,"✓","✗ Not Found")) -> ✓
A3: jane.doe@company.com | B3: Jane Doe | C3: supervisor | D3: admin | E3: admin | F3: Day Shift Team | G3: Machining | H3: =IF(F3="","",IF(COUNTIF(Teams!A$2:A$6,F3)>0,"✓","✗ Not Found")) -> ✓
A4: mike.wilson@company.com | B4: Mike Wilson | C4: operator | D4: member | E4: member | F4: Welding Team | G4: Fabrication | H4: =IF(F4="","",IF(COUNTIF(Teams!A$2:A$6,F4)>0,"✓","✗ Not Found")) -> ✓
A5: sarah.johnson@company.com | B5: Sarah Johnson | C5: admin | D5: owner | H5: =IF(F5="","",IF(COUNTIF(Teams!A$2:A$6,F5)>0,"✓","✗ Not Found"))
A6: tom.brown@company.com | B6: Tom Brown | C6: viewer | D6: member | F6: Quality Team | G6: Quality | H6: =IF(F6="","",IF(COUNTIF(Teams!A$2:A$6,F6)>0,"✓","✗ Not Found")) -> ✓

Sheet Users - Valid Values
A1: Column | B1: Valid Values
A2: App Role | B2: admin, supervisor, operator, viewer
A3: Org Role (optional) | B3: owner, admin, member
A4: Team Role (optional) | B4: owner, admin, member

Sheet Work Orders
A1: Work Order # | B1: Title | C1: Part Number (optional) | D1: Operation # (optional) | E1: Quantity (optional) | F1: Priority | G1: Status | H1: Station ID (optional) | I1: Team Name (optional) | J1: Due Date (YYYY-MM-DD) | K1: Est. Duration (min) | L1: Tags (comma-separated) | M1: Description (optional) | N1: Team Valid? | O1: Station Valid?
A2: WO-2026-001 | B2: Bracket Assembly | C2: BRK-1234 | D2: 10 | E2: 50 | F2: normal | G2: pending | H2: CNC-001 | I2: Day Shift Team | J2: 2026-03-15 | K2: 120 | L2: rush,aerospace | M2: Machine brackets per drawing REV-B | N2: =IF(I2="","",IF(COUNTIF(Teams!A$2:A$6,I2)>0,"✓","✗ Not Found")) -> ✓ | O2: =IF(H2="","",IF(COUNTIF(Stations!A$2:A$19,H2)>0,"✓","✗ Not Found")) -> ✓
A3: WO-2026-002 | B3: Housing Machining | C3: HSG-5678 | D3: 20 | E3: 25 | F3: high | G3: queued | H3: LATHE-001 | I3: Night Shift Team | J3: 2026-03-12 | K3: 240 | L3: priority | M3: Turn housing components | N3: =IF(I3="","",IF(COUNTIF(Teams!A$2:A$6,I3)>0,"✓","✗ Not Found")) -> ✓ | O3: =IF(H3="","",IF(COUNTIF(Stations!A$2:A$19,H3)>0,"✓","✗ Not Found")) -> ✓
A4: WO-2026-003 | B4: Cover Plate Inspection | C4: CVR-9012 | D4: 30 | E4: 100 | F4: normal | G4: pending | H4: INSP-001 | I4: Quality Team | J4: 2026-03-20 | K4: 60 | M4: Final inspection of cover plates | N4: =IF(I4="","",IF(COUNTIF(Teams!A$2:A$6,I4)>0,"✓","✗ Not Found")) -> ✓ | O4: =IF(H4="","",IF(COUNTIF(Stations!A$2:A$19,H4)>0,"✓","✗ Not Found")) -> ✓
A5: WO-2026-004 | B5: Shaft Grinding | C5: SFT-3456 | D5: 40 | E5: 10 | F5: urgent | G5: pending | I5: Day Shift Team | J5: 2026-03-10 | K5: 180 | L5: hot-job,customer-urgent | M5: Precision grinding per spec | N5: =IF(I5="","",IF(COUNTIF(Teams!A$2:A$6,I5)>0,"✓","✗ Not Found")) -> ✓ | O5: =IF(H5="","",IF(COUNTIF(Stations!A$2:A$19,H5)>0,"✓","✗ Not Found"))
A6: WO-2026-005 | B6: Prototype Frame | C6: FRM-7890 | D6: 10 | E6: 2 | F6: critical | G6: in_progress | H6: WELD-001 | I6: Welding Team | J6: 2026-03-08 | K6: 480 | L6: prototype,engineering | M6: New product prototype frame | N6: =IF(I6="","",IF(COUNTIF(Teams!A$2:A$6,I6)>0,"✓","✗ Not Found")) -> ✓ | O6: =IF(H6="","",IF(COUNTIF(Stations!A$2:A$19,H6)>0,"✓","✗ Not Found")) -> ✓

Sheet Work Orders - Valid Values
A1: Column | B1: Valid Values
A2: Priority | B2: low, normal, high, urgent, critical
A3: Status | B3: pending, queued, in_progress, on_hold

Sheet Routing Templates
A1: Template Name | B1: Part Number Pattern | C1: Step # | D1: Operation Name | E1: Type | F1: Work Center | G1: Est. Duration (min) | H1: Vendor (if outside) | I1: Instructions
A2: Standard Manufacturing | B2: PART-* | C2: 1 | D2: Quote Review & Approval | E2: quote | F2: Front Office | G2: 30 | I2: Review quote and customer requirements
A3: Standard Manufacturing | B3: PART-* | C3: 2 | D3: Engineering Review | E3: engineering | F3: Engineering Office | G3: 60 | I3: Review drawings, tolerances, and material specs
A4: Standard Manufacturing | B4: PART-* | C4: 3 | D4: Programming/CAM | E4: engineering | F4: Engineering Office | G4: 120 | I4: Create CNC programs and toolpaths
A5: Standard Manufacturing | B5: PART-* | C5: 4 | D5: Materials Purchasing | E5: purchasing | F5: Front Office | G5: 30 | I5: Order raw materials and special tooling
A6: Standard Manufacturing | B6: PART-* | C6: 5 | D6: Materials Receiving | E6: receiving | F6: Receiving Area | G6: 15 | I6: Receive and verify material certifications
A7: Standard Manufacturing | B7: PART-* | C7: 6 | D7: Incoming Inspection | E7: inspection | F7: Quality Lab | G7: 30 | I7: Verify material dimensions and condition
A8: Standard Manufacturing | B8: PART-* | C8: 7 | D8: Material Cutting/Prep | E8: internal | F8: Cutting Area | G8: 30 | I8: Cut material to rough size
A9: Standard Manufacturing | B9: PART-* | C9: 8 | D9: Tool Setup & Prep | E9: internal | F9: Tool Crib Area | G9: 45 | I9: Pull and verify tooling, fixtures, and gages
A10: Standard Manufacturing | B10: PART-* | C10: 9 | D10: First Article Setup | E10: internal | F10: CNC Bay 1 | G10: 90 | I10: Setup machine and run first article
A11: Standard Manufacturing | B11: PART-* | C11: 10 | D11: First Article Inspection | E11: inspection | F11: Quality Lab | G11: 60 | I11: Full dimensional inspection per drawing
A12: Standard Manufacturing | B12: PART-* | C12: 11 | D12: Production Run | E12: internal | F12: CNC Bay 1 | G12: 240 | I12: Complete production quantity
A13: Standard Manufacturing | B13: PART-* | C13: 12 | D13: Deburr/Finish | E13: internal | F13: Finishing Area | G13: 30 | I13: Remove burrs and clean parts
A14: Standard Manufacturing | B14: PART-* | C14: 13 | D14: Heat Treat | E14: outside_processing | G14: 480 | H14: ABC Heat Treat | I14: HRC 58-62 per spec
A15: Standard Manufacturing | B15: PART-* | C15: 14 | D15: Final Inspection | E15: inspection | F15: Quality Lab | G15: 30 | I15: Final QC check before shipping
A16: Standard Manufacturing | B16: PART-* | C16: 15 | D16: Packaging | E16: internal | F16: Shipping Area | G16: 15 | I16: Package per customer requirements
A17: Standard Manufacturing | B17: PART-* | C17: 16 | D17: Ship to Customer | E17: shipping | F17: Shipping Area | G17: 15 | I17: Generate shipping labels and ship

Sheet Routing Templates - Valid Values
A1: Column | B1: Valid Values
A2: Type | B2: quote, engineering, purchasing, receiving, internal, outside_processing, inspection, shipping
